Workbook

Sheet Messy_Employee_dataset
A1: Employee_ID | B1: First_Name | C1: Last_Name | D1: Age | E1: Department_Region | F1: Status | G1: Join_Date | H1: Salary | I1: Email | J1: Phone | K1: Performance_Score | L1: Remote_Work
A2: EMP1000 | B2: Bob | C2: Davis | D2: 25 | E2: DevOps-California | F2: Active | G2: 44288 | H2: 59767.65 | I2: bob.davis@example.com | J2: -1651623197 | K2: Average | L2: TRUE
A3: EMP1001 | B3: Bob | C3: Brown | E3: Finance-Texas | F3: Active | G3: 44022 | H3: 65304.66 | I3: bob.brown@example.com | J3: -1898471390 | K3: Excellent | L3: TRUE
A4: EMP1002 | B4: Alice | C4: Jones | E4: Admin-Nevada | F4: Pending | G4: 45267 | H4: 88145.9 | I4: alice.jones@example.com | J4: -5596363211 | K4: Good | L4: TRUE
A5: EMP1003 | B5: Eva | C5: Davis | D5: 25 | E5: Admin-Nevada | F5: Inactive | G5: 44527 | H5: 69450.99 | I5: eva.davis@example.com | J5: -3476490784 | K5: Good | L5: TRUE
A6: EMP1004 | B6: Frank | C6: Williams | D6: 25 | E6: Cloud Tech-Florida | F6: Active | G6: 44566 | H6: 109324.61 | I6: frank.williams@example.com | J6: -1586734256 | K6: Poor | L6: FALSE
A7: EMP1005 | B7: Alice | C7: Garcia | D7: 40 | E7: Sales-Texas | F7: Inactive | G7: 43992 | H7: 88642.84 | I7: alice.garcia@example.com | J7: -5409003485 | K7: Good | L7: FALSE
A8: EMP1006 | B8: Frank | C8: Jones | E8: Admin-Nevada | F8: Active | G8: 43924 | H8: 96288.43 | I8: frank.jones@example.com | J8: -4518376063 | K8: Good | L8: FALSE
A9: EMP1007 | B9: Bob | C9: Jones | D9: 30 | E9: Cloud Tech-Florida | F9: Inactive | G9: 44759 | H9: 94497.91 | I9: bob.jones@example.com | J9: -4134327559 | K9: Average | L9: TRUE
A10: EMP1008 | B10: Frank | C10: Davis | D10: 35 | E10: Admin-Nevada | F10: Inactive | G10: 45268 | H10: 115565.82 | I10: frank.davis@example.com | J10: -4177656123 | K10: Excellent | L10: TRUE
A11: EMP1009 | B11: Charlie | C11: Johnson | E11: DevOps-New York | F11: Active | G11: 44777 | H11: 76561.88 | I11: charlie.johnson@example.com | J11: -8156985699 | K11: Excellent | L11: TRUE
A12: EMP1010 | B12: David | C12: Williams | D12: 35 | E12: Cloud Tech-New York | F12: Active | G12: 45479 | H12: 72081.71 | I12: david.williams@example.com | J12: -2720634590 | K12: Average | L12: FALSE
A13: EMP1011 | B13: David | C13: Davis | E13: DevOps-California | F13: Active | G13: 45173 | H13: 84946.19 | I13: david.davis@example.com | J13: -1238296576 | K13: Poor | L13: TRUE
A14: EMP1012 | B14: Heidi | C14: Williams | D14: 30 | E14: HR-New York | F14: Active | G14: 45356 | H14: 89295.77 | I14: heidi.williams@example.com | J14: -2429543164 | K14: Excellent | L14: FALSE
A15: EMP1013 | B15: Grace | C15: Williams | E15: Finance-California | F15: Active | G15: 44114 | H15: 85666.84 | I15: grace.williams@example.com | J15: -2669300892 | K15: Good | L15: FALSE
A16: EMP1014 | B16: Alice | C16: Garcia | D16: 25 | E16: Admin-Nevada | F16: Active | G16: 45453 | H16: 97633.68 | I16: alice.garcia@example.com | J16: -1734206968 | K16: Excellent | L16: TRUE
A17: EMP1015 | B17: Grace | C17: Jones | D17: 40 | E17: Sales-Florida | F17: Pending | G17: 44345 | H17: 117975.49 | I17: grace.jones@example.com | J17: -4215291085 | K17: Good | L17: TRUE
A18: EMP1016 | B18: Alice | C18: Brown | D18: 25 | E18: DevOps-Illinois | F18: Inactive | G18: 45405 | H18: 94867.33 | I18: alice.brown@example.com | J18: -7713334475 | K18: Poor | L18: FALSE
A19: EMP1017 | B19: Grace | C19: Garcia | D19: 30 | E19: Finance-Texas | F19: Pending | G19: 45624 | H19: 100377.65 | I19: grace.garcia@example.com | J19: -2639343625 | K19: Average | L19: TRUE
A20: EMP1018 | B20: Charlie | C20: Garcia | E20: Cloud Tech-Nevada | F20: Inactive | G20: 45554 | H20: 94726.46 | I20: charlie.garcia@example.com | J20: -2044397358 | K20: Excellent | L20: FALSE
A21: EMP1019 | B21: Charlie | C21: Williams | D21: 35 | E21: Admin-Illinois | F21: Pending | G21: 43832 | H21: 91926.12 | I21: charlie.williams@example.com | J21: -7107256365 | K21: Average | L21: TRUE
A22: EMP1020 | B22: Bob | C22: Miller | D22: 35 | E22: HR-New York | F22: Active | G22: 44324 | H22: 111460.67 | I22: bob.miller@example.com | J22: -9411800536 | K22: Excellent | L22: TRUE
A23: EMP1021 | B23: Bob | C23: Jones | D23: 40 | E23: Cloud Tech-Illinois | F23: Active | G23: 44093 | H23: 96182.56 | I23: bob.jones@example.com | J23: -5990048963 | K23: Good | L23: FALSE
A24: EMP1022 | B24: Charlie | C24: Johnson | D24: 35 | E24: Sales-Illinois | F24: Inactive | G24: 44264 | H24: 115023.94 | I24: charlie.johnson@example.com | J24: -6528092427 | K24: Average | L24: TRUE
A25: EMP1023 | B25: David | C25: Garcia | D25: 35 | E25: Finance-Nevada | F25: Pending | G25: 44595 | H25: 80667.01 | I25: david.garcia@example.com | J25: -7572158623 | K25: Excellent | L25: FALSE
A26: EMP1024 | B26: Bob | C26: Brown | D26: 30 | E26: Admin-Texas | F26: Inactive | G26: 43874 | H26: 91181.61 | I26: bob.brown@example.com | J26: -1502745643 | K26: Good | L26: TRUE
A27: EMP1025 | B27: David | C27: Miller | D27: 25 | E27: Cloud Tech-Nevada | F27: Pending | G27: 43951 | H27: 66025.92 | I27: david.miller@example.com | J27: -9485625727 | K27: Average | L27: FALSE
A28: EMP1026 | B28: Frank | C28: Miller | D28: 25 | E28: Sales-New York | F28: Inactive | G28: 45201 | H28: 83979.01 | I28: frank.miller@example.com | J28: -7032032073 | K28: Average | L28: FALSE
A29: EMP1027 | B29: Heidi | C29: Johnson | D29: 30 | E29: Finance-Florida | F29: Active | G29: 44024 | H29: 56785.16 | I29: heidi.johnson@example.com | J29: -2761707586 | K29: Excellent | L29: TRUE
A30: EMP1028 | B30: Grace | C30: Garcia | D30: 40 | E30: Finance-Nevada | F30: Active | G30: 45210 | H30: 95741.88 | I30: grace.garcia@example.com | J30: -7712151341 | K30: Excellent | L30: FALSE
A31: EMP1029 | B31: Alice | C31: Brown | D31: 40 | E31: DevOps-California | F31: Active | G31: 44340 | H31: 63411.31 | I31: alice.brown@example.com | J31: -2849939088 | K31: Excellent | L31: TRUE
A32: EMP1030 | B32: Charlie | C32: Jones | D32: 40 | E32: Admin-California | F32: Inactive | G32: 44342 | H32: 111214.02 | I32: charlie.jones@example.com | J32: -2613715040 | K32: Good | L32: TRUE
... A37: EMP1035 | B37: Frank | C37: Jones | D37: 25 | E37: Cloud Tech-Illinois | F37: Inactive | G37: 44860 | H37: 114357.1 | I37: frank.jones@example.com | J37: -6642147648 | K37: Excellent | L37: TRUE
A38: EMP1036 | B38: Alice | C38: Brown | E38: Cloud Tech-New York | F38: Active | G38: 45049 | H38: 54757.26 | I38: alice.brown@example.com | J38: -2515837766 | K38: Poor | L38: FALSE
A39: EMP1037 | B39: Grace | C39: Smith | D39: 25 | E39: Sales-New York | F39: Pending | G39: 45048 | H39: 52781.92 | I39: grace.smith@example.com | J39: -4996165925 | K39: Average | L39: TRUE
A40: EMP1038 | B40: Frank | C40: Smith | D40: 35 | E40: Admin-Nevada | F40: Pending | G40: 44474 | H40: 66708.02 | I40: frank.smith@example.com | J40: -6108573277 | K40: Good | L40: TRUE
A41: EMP1039 | B41: Eva | C41: Williams | D41: 40 | E41: HR-Texas | F41: Active | G41: 44769 | H41: 93481.15 | I41: eva.williams@example.com | J41: -8147617421 | K41: Poor | L41: FALSE
A42: EMP1040 | B42: Bob | C42: Williams | D42: 25 | E42: Sales-New York | F42: Pending | G42: 44374 | H42: 59271.96 | I42: bob.williams@example.com | J42: -4386490809 | K42: Excellent | L42: TRUE
A43: EMP1041 | B43: Bob | C43: Davis | D43: 30 | E43: HR-California | F43: Active | G43: 44728 | H43: 108362.15 | I43: bob.davis@example.com | J43: -8186617944 | K43: Excellent | L43: FALSE
A44: EMP1042 | B44: Alice | C44: Johnson | E44: HR-Nevada | F44: Active | G44: 45629 | H44: 59400.38 | I44: alice.johnson@example.com | J44: -4918017225 | K44: Average | L44: TRUE
...

Sheet Table_Employee
A1: Employee_ID | B1: First_Name | C1: Last_Name | D1: Age | E1: Department | F1: Region | G1: Status | H1: Join_Date | I1: Salary | J1: Email | K1: Phone | L1: Performance_Score | M1: Remote_Work | N1: Salary_fill | O1: Format_Phone | P1: Phone_AF | Q1: Name_Concat | R1: Tenure | S1: NameConReg
A2: EMP1000 | B2: Bob | C2: Davis | D2: 25 | E2: DevOps | F2: California | G2: Active | H2: 44288 | I2: 59767.65 | J2: bob.davis@example.com | K2: -1651623197 | L2: Average | M2: TRUE | N2: {=IF(Table_Employee!I2="N/A", IFERROR(MEDIAN(_xlfn._xlws.FILTER(Table_Employee_Clean[Salary], (Table_Employee_Clean[Department] = Table_Employee!E2) * (Table_Employee_Clean[Region] = Table_Employee!F2))), "N/A"), Table_Employee!I2)} -> 59767.65 | O2: =" "&SUBSTITUTE(Table_Employee_Clean[[#This Row],[Phone]],"-","") -> 1651623197 | P2: =TEXT(Table_Employee_Clean[[#This Row],[Format_Phone]],"(000) 000-0000") -> (165) 162-3197 | Q2: =CONCATENATE(TRIM(Table_Employee_Clean[[#This Row],[First_Name]])," ",TRIM(Table_Employee_Clean[[#This Row],[Last_Name]])) -> Bob Davis | R2: =DATEDIF(Table_Employee_Clean[[#This Row],[Join_Date]], TODAY(), "y") -> 5 | S2: =CONCATENATE(TRIM(Table_Employee_Clean[[#This Row],[Name_Concat]])," FROM ",TRIM(Table_Employee_Clean[[#This Row],[Region]])) -> Bob Davis FROM California
A3: EMP1001 | B3: Bob | C3: Brown | D3: 30 | E3: Finance | F3: Texas | G3: Active | H3: 44022 | I3: 65304.66 | J3: bob.brown@example.com | K3: -1898471390 | L3: Excellent | M3: TRUE | N3: {=IF(Table_Employee!I3="N/A", IFERROR(MEDIAN(_xlfn._xlws.FILTER(Table_Employee_Clean[Salary], (Table_Employee_Clean[Department] = Table_Employee!E3) * (Table_Employee_Clean[Region] = Table_Employee!F3))), "N/A"), Table_Employee!I3)} -> 65304.66 | O3: =" "&SUBSTITUTE(Table_Employee_Clean[[#This Row],[Phone]],"-","") -> 1898471390 | P3: =TEXT(Table_Employee_Clean[[#This Row],[Format_Phone]],"(000) 000-0000") -> (189) 847-1390 | Q3: =CONCATENATE(TRIM(Table_Employee_Clean[[#This Row],[First_Name]])," ",TRIM(Table_Employee_Clean[[#This Row],[Last_Name]])) -> Bob Brown | R3: =DATEDIF(Table_Employee_Clean[[#This Row],[Join_Date]], TODAY(), "y") -> 6 | S3: =CONCATENATE(TRIM(Table_Employee_Clean[[#This Row],[Name_Concat]])," FROM ",TRIM(Table_Employee_Clean[[#This Row],[Region]])) -> Bob Brown FROM Texas
A4: EMP1002 | B4: Alice | C4: Jones | D4: 30 | E4: Admin | F4: Nevada | G4: Pending | H4: 45267 | I4: 88145.9 | J4: alice.jones@example.com | K4: -5596363211 | L4: Good | M4: TRUE | N4: {=IF(Table_Employee!I4="N/A", IFERROR(MEDIAN(_xlfn._xlws.FILTER(Table_Employee_Clean[Salary], (Table_Employee_Clean[Department] = Table_Employee!E4) * (Table_Employee_Clean[Region] = Table_Employee!F4))), "N/A"), Table_Employee!I4)} -> 88145.9 | O4: =" "&SUBSTITUTE(Table_Employee_Clean[[#This Row],[Phone]],"-","") -> 5596363211 | P4: =TEXT(Table_Employee_Clean[[#This Row],[Format_Phone]],"(000) 000-0000") -> (559) 636-3211 | Q4: =CONCATENATE(TRIM(Table_Employee_Clean[[#This Row],[First_Name]])," ",TRIM(Table_Employee_Clean[[#This Row],[Last_Name]])) -> Alice Jones | R4: =DATEDIF(Table_Employee_Clean[[#This Row],[Join_Date]], TODAY(), "y") -> 2 | S4: =CONCATENATE(TRIM(Table_Employee_Clean[[#This Row],[Name_Concat]])," FROM ",TRIM(Table_Employee_Clean[[#This Row],[Region]])) -> Alice Jones FROM Nevada
A5: EMP1003 | B5: Eva | C5: Davis | D5: 25 | E5: Admin | F5: Nevada | G5: Inactive | H5: 44527 | I5: 69450.99 | J5: eva.davis@example.com | K5: -3476490784 | L5: Good | M5: TRUE | N5: {=IF(Table_Employee!I5="N/A", IFERROR(MEDIAN(_xlfn._xlws.FILTER(Table_Employee_Clean[Salary], (Table_Employee_Clean[Department] = Table_Employee!E5) * (Table_Employee_Clean[Region] = Table_Employee!F5))), "N/A"), Table_Employee!I5)} -> 69450.99 | O5: =" "&SUBSTITUTE(Table_Employee_Clean[[#This Row],[Phone]],"-","") -> 3476490784 | P5: =TEXT(Table_Employee_Clean[[#This Row],[Format_Phone]],"(000) 000-0000") -> (347) 649-0784 | Q5: =CONCATENATE(TRIM(Table_Employee_Clean[[#This Row],[First_Name]])," ",TRIM(Table_Employee_Clean[[#This Row],[Last_Name]])) -> Eva Davis | R5: =DATEDIF(Table_Employee_Clean[[#This Row],[Join_Date]], TODAY(), "y") -> 4 | S5: =CONCATENATE(TRIM(Table_Employee_Clean[[#This Row],[Name_Concat]])," FROM ",TRIM(Table_Employee_Clean[[#This Row],[Region]])) -> Eva Davis FROM Nevada
A6: EMP1004 | B6: Frank | C6: Williams | D6: 25 | E6: Cloud Tech | F6: Florida | G6: Active | H6: 44566 | I6: 109324.61 | J6: frank.williams@example.com | K6: -1586734256 | L6: Poor | M6: FALSE | N6: {=IF(Table_Employee!I6="N/A", IFERROR(MEDIAN(_xlfn._xlws.FILTER(Table_Employee_Clean[Salary], (Table_Employee_Clean[Department] = Table_Employee!E6) * (Table_Employee_Clean[Region] = Table_Employee!F6))), "N/A"), Table_Employee!I6)} -> 109324.61 | O6: =" "&SUBSTITUTE(Table_Employee_Clean[[#This Row],[Phone]],"-","") -> 1586734256 | P6: =TEXT(Table_Employee_Clean[[#This Row],[Format_Phone]],"(000) 000-0000") -> (158) 673-4256 | Q6: =CONCATENATE(TRIM(Table_Employee_Clean[[#This Row],[First_Name]])," ",TRIM(Table_Employee_Clean[[#This Row],[Last_Name]])) -> Frank Williams | R6: =DATEDIF(Table_Employee_Clean[[#This Row],[Join_Date]], TODAY(), "y") -> 4 | S6: =CONCATENATE(TRIM(Table_Employee_Clean[[#This Row],[Name_Concat]])," FROM ",TRIM(Table_Employee_Clean[[#This Row],[Region]])) -> Frank Williams FROM Florida
A7: EMP1005 | B7: Alice | C7: Garcia | D7: 40 | E7: Sales | F7: Texas | G7: Inactive | H7: 43992 | I7: 88642.84 | J7: alice.garcia@example.com | K7: -5409003485 | L7: Good | M7: FALSE | N7: {=IF(Table_Employee!I7="N/A", IFERROR(MEDIAN(_xlfn._xlws.FILTER(Table_Employee_Clean[Salary], (Table_Employee_Clean[Department] = Table_Employee!E7) * (Table_Employee_Clean[Region] = Table_Employee!F7))), "N/A"), Table_Employee!I7)} -> 88642.84 | O7: =" "&SUBSTITUTE(Table_Employee_Clean[[#This Row],[Phone]],"-","") -> 5409003485 | P7: =TEXT(Table_Employee_Clean[[#This Row],[Format_Phone]],"(000) 000-0000") -> (540) 900-3485 | Q7: =CONCATENATE(TRIM(Table_Employee_Clean[[#This Row],[First_Name]])," ",TRIM(Table_Employee_Clean[[#This Row],[Last_Name]])) -> Alice Garcia | R7: =DATEDIF(Table_Employee_Clean[[#This Row],[Join_Date]], TODAY(), "y") -> 6 | S7: =CONCATENATE(TRIM(Table_Employee_Clean[[#This Row],[Name_Concat]])," FROM ",TRIM(Table_Employee_Clean[[#This Row],[Region]])) -> Alice Garcia FROM Texas
A8: EMP1006 | B8: Frank | C8: Jones | D8: 30 | E8: Admin | F8: Nevada | G8: Active | H8: 43924 | I8: 96288.43 | J8: frank.jones@example.com | K8: -4518376063 | L8: Good | M8: FALSE | N8: {=IF(Table_Employee!I8="N/A", IFERROR(MEDIAN(_xlfn._xlws.FILTER(Table_Employee_Clean[Salary], (Table_Employee_Clean[Department] = Table_Employee!E8) * (Table_Employee_Clean[Region] = Table_Employee!F8))), "N/A"), Table_Employee!I8)} -> 96288.43 | O8: =" "&SUBSTITUTE(Table_Employee_Clean[[#This Row],[Phone]],"-","") -> 4518376063 | P8: =TEXT(Table_Employee_Clean[[#This Row],[Format_Phone]],"(000) 000-0000") -> (451) 837-6063 | Q8: =CONCATENATE(TRIM(Table_Employee_Clean[[#This Row],[First_Name]])," ",TRIM(Table_Employee_Clean[[#This Row],[Last_Name]])) -> Frank Jones | R8: =DATEDIF(Table_Employee_Clean[[#This Row],[Join_Date]], TODAY(), "y") -> 6 | S8: =CONCATENATE(TRIM(Table_Employee_Clean[[#This Row],[Name_Concat]])," FROM ",TRIM(Table_Employee_Clean[[#This Row],[Region]])) -> Frank Jones FROM Nevada
A9: EMP1007 | B9: Bob | C9: Jones | D9: 30 | E9: Cloud Tech | F9: Florida | G9: Inactive | H9: 44759 | I9: 94497.91 | J9: bob.jones@example.com | K9: -4134327559 | L9: Average | M9: TRUE | N9: {=IF(Table_Employee!I9="N/A", IFERROR(MEDIAN(_xlfn._xlws.FILTER(Table_Employee_Clean[Salary], (Table_Employee_Clean[Department] = Table_Employee!E9) * (Table_Employee_Clean[Region] = Table_Employee!F9))), "N/A"), Table_Employee!I9)} -> 94497.91 | O9: =" "&SUBSTITUTE(Table_Employee_Clean[[#This Row],[Phone]],"-","") -> 4134327559 | P9: =TEXT(Table_Employee_Clean[[#This Row],[Format_Phone]],"(000) 000-0000") -> (413) 432-7559 | Q9: =CONCATENATE(TRIM(Table_Employee_Clean[[#This Row],[First_Name]])," ",TRIM(Table_Employee_Clean[[#This Row],[Last_Name]])) -> Bob Jones | R9: =DATEDIF(Table_Employee_Clean[[#This Row],[Join_Date]], TODAY(), "y") -> 4 | S9: =CONCATENATE(TRIM(Table_Employee_Clean[[#This Row],[Name_Concat]])," FROM ",TRIM(Table_Employee_Clean[[#This Row],[Region]])) -> Bob Jones FROM Florida
A10: EMP1008 | B10: Frank | C10: Davis | D10: 35 | E10: Admin | F10: Nevada | G10: Inactive | H10: 45268 | I10: 115565.82 | J10: frank.davis@example.com | K10: -4177656123 | L10: Excellent | M10: TRUE | N10: {=IF(Table_Employee!I10="N/A", IFERROR(MEDIAN(_xlfn._xlws.FILTER(Table_Employee_Clean[Salary], (Table_Employee_Clean[Department] = Table_Employee!E10) * (Table_Employee_Clean[Region] = Table_Employee!F10))), "N/A"), Table_Employee!I10)} -> 115565.82 | O10: =" "&SUBSTITUTE(Table_Employee_Clean[[#This Row],[Phone]],"-","") -> 4177656123 | P10: =TEXT(Table_Employee_Clean[[#This Row],[Format_Phone]],"(000) 000-0000") -> (417) 765-6123 | Q10: =CONCATENATE(TRIM(Table_Employee_Clean[[#This Row],[First_Name]])," ",TRIM(Table_Employee_Clean[[#This Row],[Last_Name]])) -> Frank Davis | R10: =DATEDIF(Table_Employee_Clean[[#This Row],[Join_Date]], TODAY(), "y") -> 2 | S10: =CONCATENATE(TRIM(Table_Employee_Clean[[#This Row],[Name_Concat]])," FROM ",TRIM(Table_Employee_Clean[[#This Row],[Region]])) -> Frank Davis FROM Nevada
A11: EMP1009 | B11: Charlie | C11: Johnson | D11: 30 | E11: DevOps | F11: New York | G11: Active | H11: 44777 | I11: 76561.88 | J11: charlie.johnson@example.com | K11: -8156985699 | L11: Excellent | M11: TRUE | N11: {=IF(Table_Employee!I11="N/A", IFERROR(MEDIAN(_xlfn._xlws.FILTER(Table_Employee_Clean[Salary], (Table_Employee_Clean[Department] = Table_Employee!E11) * (Table_Employee_Clean[Region] = Table_Employee!F11))), "N/A"), Table_Employee!I11)} -> 76561.88 | O11: =" "&SUBSTITUTE(Table_Employee_Clean[[#This Row],[Phone]],"-","") -> 8156985699 | P11: =TEXT(Table_Employee_Clean[[#This Row],[Format_Phone]],"(000) 000-0000") -> (815) 698-5699 | Q11: =CONCATENATE(TRIM(Table_Employee_Clean[[#This Row],[First_Name]])," ",TRIM(Table_Employee_Clean[[#This Row],[Last_Name]])) -> Charlie Johnson | R11: =DATEDIF(Table_Employee_Clean[[#This Row],[Join_Date]], TODAY(), "y") -> 4 | S11: =CONCATENATE(TRIM(Table_Employee_Clean[[#This Row],[Name_Concat]])," FROM ",TRIM(Table_Employee_Clean[[#This Row],[Region]])) -> Charlie Johnson FROM New York
A12: EMP1010 | B12: David | C12: Williams | D12: 35 | E12: Cloud Tech | F12: New York | G12: Active | H12: 45479 | I12: 72081.71 | J12: david.williams@example.com | K12: -2720634590 | L12: Average | M12: FALSE | N12: {=IF(Table_Employee!I12="N/A", IFERROR(MEDIAN(_xlfn._xlws.FILTER(Table_Employee_Clean[Salary], (Table_Employee_Clean[Department] = Table_Employee!E12) * (Table_Employee_Clean[Region] = Table_Employee!F12))), "N/A"), Table_Employee!I12)} -> 72081.71 | O12: =" "&SUBSTITUTE(Table_Employee_Clean[[#This Row],[Phone]],"-","") -> 2720634590 | P12: =TEXT(Table_Employee_Clean[[#This Row],[Format_Phone]],"(000) 000-0000") -> (272) 063-4590 | Q12: =CONCATENATE(TRIM(Table_Employee_Clean[[#This Row],[First_Name]])," ",TRIM(Table_Employee_Clean[[#This Row],[Last_Name]])) -> David Williams | R12: =DATEDIF(Table_Employee_Clean[[#This Row],[Join_Date]], TODAY(), "y") -> 2 | S12: =CONCATENATE(TRIM(Table_Employee_Clean[[#This Row],[Name_Concat]])," FROM ",TRIM(Table_Employee_Clean[[#This Row],[Region]])) -> David Williams FROM New York
A13: EMP1011 | B13: David | C13: Davis | D13: 30 | E13: DevOps | F13: California | G13: Active | H13: 45173 | I13: 84946.19 | J13: david.davis@example.com | K13: -1238296576 | L13: Poor | M13: TRUE | N13: {=IF(Table_Employee!I13="N/A", IFERROR(MEDIAN(_xlfn._xlws.FILTER(Table_Employee_Clean[Salary], (Table_Employee_Clean[Department] = Table_Employee!E13) * (Table_Employee_Clean[Region] = Table_Employee!F13))), "N/A"), Table_Employee!I13)} -> 84946.19 | O13: =" "&SUBSTITUTE(Table_Employee_Clean[[#This Row],[Phone]],"-","") -> 1238296576 | P13: =TEXT(Table_Employee_Clean[[#This Row],[Format_Phone]],"(000) 000-0000") -> (123) 829-6576 | Q13: =CONCATENATE(TRIM(Table_Employee_Clean[[#This Row],[First_Name]])," ",TRIM(Table_Employee_Clean[[#This Row],[Last_Name]])) -> David Davis | R13: =DATEDIF(Table_Employee_Clean[[#This Row],[Join_Date]], TODAY(), "y") -> 3 | S13: =CONCATENATE(TRIM(Table_Employee_Clean[[#This Row],[Name_Concat]])," FROM ",TRIM(Table_Employee_Clean[[#This Row],[Region]])) -> David Davis FROM California
... A100: EMP1098 | B100: Bob | C100: Miller | D100: 30 | E100: DevOps | F100: New York | G100: Active | H100: 44274 | I100: 101702.33 | J100: bob.miller@example.com | K100: -3824967182 | L100: Excellent | M100: FALSE | N100: {=IF(Table_Employee!I100="N/A", IFERROR(MEDIAN(_xlfn._xlws.FILTER(Table_Employee_Clean[Salary], (Table_Employee_Clean[Department] = Table_Employee!E100) * (Table_Employee_Clean[Region] = Table_Employee!F100))), "N/A"), Table_Employee!I100)} -> 101702.33 | O100: =" "&SUBSTITUTE(Table_Employee_Clean[[#This Row],[Phone]],"-","") -> 3824967182 | P100: =TEXT(Table_Employee_Clean[[#This Row],[Format_Phone]],"(000) 000-0000") -> (382) 496-7182 | Q100: =CONCATENATE(TRIM(Table_Employee_Clean[[#This Row],[First_Name]])," ",TRIM(Table_Employee_Clean[[#This Row],[Last_Name]])) -> Bob Miller | R100: =DATEDIF(Table_Employee_Clean[[#This Row],[Join_Date]], TODAY(), "y") -> 5 | S100: =CONCATENATE(TRIM(Table_Employee_Clean[[#This Row],[Name_Concat]])," FROM ",TRIM(Table_Employee_Clean[[#This Row],[Region]])) -> Bob Miller FROM New York
A101: EMP1099 | B101: Eva | C101: Jones | D101: 25 | E101: Admin | F101: California | G101: Active | H101: 44570 | I101: N/A | J101: eva.jones@example.com | K101: -2582386869 | L101: Good | M101: FALSE | N101: {=IF(Table_Employee!I101="N/A", IFERROR(MEDIAN(_xlfn._xlws.FILTER(Table_Employee_Clean[Salary], (Table_Employee_Clean[Department] = Table_Employee!E101) * (Table_Employee_Clean[Region] = Table_Employee!F101))), "N/A"), Table_Employee!I101)} -> 93772.61 | O101: =" "&SUBSTITUTE(Table_Employee_Clean[[#This Row],[Phone]],"-","") -> 2582386869 | P101: =TEXT(Table_Employee_Clean[[#This Row],[Format_Phone]],"(000) 000-0000") -> (258) 238-6869 | Q101: =CONCATENATE(TRIM(Table_Employee_Clean[[#This Row],[First_Name]])," ",TRIM(Table_Employee_Clean[[#This Row],[Last_Name]])) -> Eva Jones | R101: =DATEDIF(Table_Employee_Clean[[#This Row],[Join_Date]], TODAY(), "y") -> 4 | S101: =CONCATENATE(TRIM(Table_Employee_Clean[[#This Row],[Name_Concat]])," FROM ",TRIM(Table_Employee_Clean[[#This Row],[Region]])) -> Eva Jones FROM California
A102: EMP1100 | B102: Charlie | C102: Davis | D102: 35 | E102: Cloud Tech | F102: Texas | G102: Pending | H102: 44429 | I102: 98819.22 | J102: charlie.davis@example.com | K102: -794200748 | L102: Good | M102: FALSE | N102: {=IF(Table_Employee!I102="N/A", IFERROR(MEDIAN(_xlfn._xlws.FILTER(Table_Employee_Clean[Salary], (Table_Employee_Clean[Department] = Table_Employee!E102) * (Table_Employee_Clean[Region] = Table_Employee!F102))), "N/A"), Table_Employee!I102)} -> 98819.22 | O102: =" "&SUBSTITUTE(Table_Employee_Clean[[#This Row],[Phone]],"-","") -> 794200748 | P102: =TEXT(Table_Employee_Clean[[#This Row],[Format_Phone]],"(000) 000-0000") -> (079) 420-0748 | Q102: =CONCATENATE(TRIM(Table_Employee_Clean[[#This Row],[First_Name]])," ",TRIM(Table_Employee_Clean[[#This Row],[Last_Name]])) -> Charlie Davis | R102: =DATEDIF(Table_Employee_Clean[[#This Row],[Join_Date]], TODAY(), "y") -> 5 | S102: =CONCATENATE(TRIM(Table_Employee_Clean[[#This Row],[Name_Concat]])," FROM ",TRIM(Table_Employee_Clean[[#This Row],[Region]])) -> Charlie Davis FROM Texas
A103: EMP1101 | B103: Heidi | C103: Johnson | D103: 25 | E103: Cloud Tech | F103: Illinois | G103: Inactive | H103: 44792 | I103: 83509.99 | J103: heidi.johnson@example.com | K103: -4653984027 | L103: Average | M103: FALSE | N103: {=IF(Table_Employee!I103="N/A", IFERROR(MEDIAN(_xlfn._xlws.FILTER(Table_Employee_Clean[Salary], (Table_Employee_Clean[Department] = Table_Employee!E103) * (Table_Employee_Clean[Region] = Table_Employee!F103))), "N/A"), Table_Employee!I103)} -> 83509.99 | O103: =" "&SUBSTITUTE(Table_Employee_Clean[[#This Row],[Phone]],"-","") -> 4653984027 | P103: =TEXT(Table_Employee_Clean[[#This Row],[Format_Phone]],"(000) 000-0000") -> (465) 398-4027 | Q103: =CONCATENATE(TRIM(Table_Employee_Clean[[#This Row],[First_Name]])," ",TRIM(Table_Employee_Clean[[#This Row],[Last_Name]])) -> Heidi Johnson | R103: =DATEDIF(Table_Employee_Clean[[#This Row],[Join_Date]], TODAY(), "y") -> 4 | S103: =CONCATENATE(TRIM(Table_Employee_Clean[[#This Row],[Name_Concat]])," FROM ",TRIM(Table_Employee_Clean[[#This Row],[Region]])) -> Heidi Johnson FROM Illinois
A104: EMP1102 | B104: Alice | C104: Johnson | D104: 35 | E104: Finance | F104: Texas | G104: Active | H104: 44651 | I104: 84422.26 | J104: alice.johnson@example.com | K104: -9141612845 | L104: Average | M104: FALSE | N104: {=IF(Table_Employee!I104="N/A", IFERROR(MEDIAN(_xlfn._xlws.FILTER(Table_Employee_Clean[Salary], (Table_Employee_Clean[Department] = Table_Employee!E104) * (Table_Employee_Clean[Region] = Table_Employee!F104))), "N/A"), Table_Employee!I104)} -> 84422.26 | O104: =" "&SUBSTITUTE(Table_Employee_Clean[[#This Row],[Phone]],"-","") -> 9141612845 | P104: =TEXT(Table_Employee_Clean[[#This Row],[Format_Phone]],"(000) 000-0000") -> (914) 161-2845 | Q104: =CONCATENATE(TRIM(Table_Employee_Clean[[#This Row],[First_Name]])," ",TRIM(Table_Employee_Clean[[#This Row],[Last_Name]])) -> Alice Johnson | R104: =DATEDIF(Table_Employee_Clean[[#This Row],[Join_Date]], TODAY(), "y") -> 4 | S104: =CONCATENATE(TRIM(Table_Employee_Clean[[#This Row],[Name_Concat]])," FROM ",TRIM(Table_Employee_Clean[[#This Row],[Region]])) -> Alice Johnson FROM Texas
A105: EMP1103 | B105: Alice | C105: Brown | D105: 30 | E105: Admin | F105: Illinois | G105: Inactive | H105: 44005 | I105: 119574.27 | J105: alice.brown@example.com | K105: -3985547434 | L105: Average | M105: TRUE | N105: {=IF(Table_Employee!I105="N/A", IFERROR(MEDIAN(_xlfn._xlws.FILTER(Table_Employee_Clean[Salary], (Table_Employee_Clean[Department] = Table_Employee!E105) * (Table_Employee_Clean[Region] = Table_Employee!F105))), "N/A"), Table_Employee!I105)} -> 119574.27 | O105: =" "&SUBSTITUTE(Table_Employee_Clean[[#This Row],[Phone]],"-","") -> 3985547434 | P105: =TEXT(Table_Employee_Clean[[#This Row],[Format_Phone]],"(000) 000-0000") -> (398) 554-7434 | Q105: =CONCATENATE(TRIM(Table_Employee_Clean[[#This Row],[First_Name]])," ",TRIM(Table_Employee_Clean[[#This Row],[Last_Name]])) -> Alice Brown | R105: =DATEDIF(Table_Employee_Clean[[#This Row],[Join_Date]], TODAY(), "y") -> 6 | S105: =CONCATENATE(TRIM(Table_Employee_Clean[[#This Row],[Name_Concat]])," FROM ",TRIM(Table_Employee_Clean[[#This Row],[Region]])) -> Alice Brown FROM Illinois
A106: EMP1104 | B106: Grace | C106: Johnson | D106: 30 | E106: Sales | F106: Illinois | G106: Active | H106: 45419 | I106: 86580.08 | J106: grace.johnson@example.com | K106: -5379502096 | L106: Good | M106: TRUE | N106: {=IF(Table_Employee!I106="N/A", IFERROR(MEDIAN(_xlfn._xlws.FILTER(Table_Employee_Clean[Salary], (Table_Employee_Clean[Department] = Table_Employee!E106) * (Table_Employee_Clean[Region] = Table_Employee!F106))), "N/A"), Table_Employee!I106)} -> 86580.08 | O106: =" "&SUBSTITUTE(Table_Employee_Clean[[#This Row],[Phone]],"-","") -> 5379502096 | P106: =TEXT(Table_Employee_Clean[[#This Row],[Format_Phone]],"(000) 000-0000") -> (537) 950-2096 | Q106: =CONCATENATE(TRIM(Table_Employee_Clean[[#This Row],[First_Name]])," ",TRIM(Table_Employee_Clean[[#This Row],[Last_Name]])) -> Grace Johnson | R106: =DATEDIF(Table_Employee_Clean[[#This Row],[Join_Date]], TODAY(), "y") -> 2 | S106: =CONCATENATE(TRIM(Table_Employee_Clean[[#This Row],[Name_Concat]])," FROM ",TRIM(Table_Employee_Clean[[#This Row],[Region]])) -> Grace Johnson FROM Illinois
A107: EMP1105 | B107: Heidi | C107: Johnson | D107: 35 | E107: Sales | F107: Florida | G107: Inactive | H107: 44995 | I107: 93471.91 | J107: heidi.johnson@example.com | K107: -26876810 | L107: Poor | M107: FALSE | N107: {=IF(Table_Employee!I107="N/A", IFERROR(MEDIAN(_xlfn._xlws.FILTER(Table_Employee_Clean[Salary], (Table_Employee_Clean[Department] = Table_Employee!E107) * (Table_Employee_Clean[Region] = Table_Employee!F107))), "N/A"), Table_Employee!I107)} -> 93471.91 | O107: =" "&SUBSTITUTE(Table_Employee_Clean[[#This Row],[Phone]],"-","") -> 26876810 | P107: =TEXT(Table_Employee_Clean[[#This Row],[Format_Phone]],"(000) 000-0000") -> (002) 687-6810 | Q107: =CONCATENATE(TRIM(Table_Employee_Clean[[#This Row],[First_Name]])," ",TRIM(Table_Employee_Clean[[#This Row],[Last_Name]])) -> Heidi Johnson | R107: =DATEDIF(Table_Employee_Clean[[#This Row],[Join_Date]], TODAY(), "y") -> 3 | S107: =CONCATENATE(TRIM(Table_Employee_Clean[[#This Row],[Name_Concat]])," FROM ",TRIM(Table_Employee_Clean[[#This Row],[Region]])) -> Heidi Johnson FROM Florida
A108: EMP1106 | B108: Bob | C108: Miller | D108: 30 | E108: DevOps | F108: New York | G108: Inactive | H108: 45183 | I108: 55683.12 | J108: bob.miller@example.com | K108: -8071569561 | L108: Poor | M108: TRUE | N108: {=IF(Table_Employee!I108="N/A", IFERROR(MEDIAN(_xlfn._xlws.FILTER(Table_Employee_Clean[Salary], (Table_Employee_Clean[Department] = Table_Employee!E108) * (Table_Employee_Clean[Region] = Table_Employee!F108))), "N/A"), Table_Employee!I108)} -> 55683.12 | O108: =" "&SUBSTITUTE(Table_Employee_Clean[[#This Row],[Phone]],"-","") -> 8071569561 | P108: =TEXT(Table_Employee_Clean[[#This Row],[Format_Phone]],"(000) 000-0000") -> (807) 156-9561 | Q108: =CONCATENATE(TRIM(Table_Employee_Clean[[#This Row],[First_Name]])," ",TRIM(Table_Employee_Clean[[#This Row],[Last_Name]])) -> Bob Miller | R108: =DATEDIF(Table_Employee_Clean[[#This Row],[Join_Date]], TODAY(), "y") -> 3 | S108: =CONCATENATE(TRIM(Table_Employee_Clean[[#This Row],[Name_Concat]])," FROM ",TRIM(Table_Employee_Clean[[#This Row],[Region]])) -> Bob Miller FROM New York
A109: EMP1107 | B109: Bob | C109: Brown | D109: 30 | E109: Cloud Tech | F109: Florida | G109: Inactive | H109: 45242 | I109: 91566.78 | J109: bob.brown@example.com | K109: -175370303 | L109: Good | M109: TRUE | N109: {=IF(Table_Employee!I109="N/A", IFERROR(MEDIAN(_xlfn._xlws.FILTER(Table_Employee_Clean[Salary], (Table_Employee_Clean[Department] = Table_Employee!E109) * (Table_Employee_Clean[Region] = Table_Employee!F109))), "N/A"), Table_Employee!I109)} -> 91566.78 | O109: =" "&SUBSTITUTE(Table_Employee_Clean[[#This Row],[Phone]],"-","") -> 175370303 | P109: =TEXT(Table_Employee_Clean[[#This Row],[Format_Phone]],"(000) 000-0000") -> (017) 537-0303 | Q109: =CONCATENATE(TRIM(Table_Employee_Clean[[#This Row],[First_Name]])," ",TRIM(Table_Employee_Clean[[#This Row],[Last_Name]])) -> Bob Brown | R109: =DATEDIF(Table_Employee_Clean[[#This Row],[Join_Date]], TODAY(), "y") -> 2 | S109: =CONCATENATE(TRIM(Table_Employee_Clean[[#This Row],[Name_Concat]])," FROM ",TRIM(Table_Employee_Clean[[#This Row],[Region]])) -> Bob Brown FROM Florida
A110: EMP1108 | B110: David | C110: Miller | D110: 35 | E110: DevOps | F110: California | G110: Pending | H110: 45591 | I110: 81782.19 | J110: david.miller@example.com | K110: -5319433749 | L110: Good | M110: FALSE | N110: {=IF(Table_Employee!I110="N/A", IFERROR(MEDIAN(_xlfn._xlws.FILTER(Table_Employee_Clean[Salary], (Table_Employee_Clean[Department] = Table_Employee!E110) * (Table_Employee_Clean[Region] = Table_Employee!F110))), "N/A"), Table_Employee!I110)} -> 81782.19 | O110: =" "&SUBSTITUTE(Table_Employee_Clean[[#This Row],[Phone]],"-","") -> 5319433749 | P110: =TEXT(Table_Employee_Clean[[#This Row],[Format_Phone]],"(000) 000-0000") -> (531) 943-3749 | Q110: =CONCATENATE(TRIM(Table_Employee_Clean[[#This Row],[First_Name]])," ",TRIM(Table_Employee_Clean[[#This Row],[Last_Name]])) -> David Miller | R110: =DATEDIF(Table_Employee_Clean[[#This Row],[Join_Date]], TODAY(), "y") -> 1 | S110: =CONCATENATE(TRIM(Table_Employee_Clean[[#This Row],[Name_Concat]])," FROM ",TRIM(Table_Employee_Clean[[#This Row],[Region]])) -> David Miller FROM California
A111: EMP1109 | B111: Eva | C111: Davis | D111: 30 | E111: DevOps | F111: New York | G111: Inactive | H111: 44066 | I111: 88119.37 | J111: eva.davis@example.com | K111: -4793036148 | L111: Good | M111: TRUE | N111: {=IF(Table_Employee!I111="N/A", IFERROR(MEDIAN(_xlfn._xlws.FILTER(Table_Employee_Clean[Salary], (Table_Employee_Clean[Department] = Table_Employee!E111) * (Table_Employee_Clean[Region] = Table_Employee!F111))), "N/A"), Table_Employee!I111)} -> 88119.37 | O111: =" "&SUBSTITUTE(Table_Employee_Clean[[#This Row],[Phone]],"-","") -> 4793036148 | P111: =TEXT(Table_Employee_Clean[[#This Row],[Format_Phone]],"(000) 000-0000") -> (479) 303-6148 | Q111: =CONCATENATE(TRIM(Table_Employee_Clean[[#This Row],[First_Name]])," ",TRIM(Table_Employee_Clean[[#This Row],[Last_Name]])) -> Eva Davis | R111: =DATEDIF(Table_Employee_Clean[[#This Row],[Join_Date]], TODAY(), "y") -> 6 | S111: =CONCATENATE(TRIM(Table_Employee_Clean[[#This Row],[Name_Concat]])," FROM ",TRIM(Table_Employee_Clean[[#This Row],[Region]])) -> Eva Davis FROM New York
A112: EMP1110 | B112: Eva | C112: Garcia | D112: 30 | E112: Cloud Tech | F112: Texas | G112: Active | H112: 45454 | I112: 71532.83 | J112: eva.garcia@example.com | K112: -8728399920 | L112: Good | M112: TRUE | N112: {=IF(Table_Employee!I112="N/A", IFERROR(MEDIAN(_xlfn._xlws.FILTER(Table_Employee_Clean[Salary], (Table_Employee_Clean[Department] = Table_Employee!E112) * (Table_Employee_Clean[Region] = Table_Employee!F112))), "N/A"), Table_Employee!I112)} -> 71532.83 | O112: =" "&SUBSTITUTE(Table_Employee_Clean[[#This Row],[Phone]],"-","") -> 8728399920 | P112: =TEXT(Table_Employee_Clean[[#This Row],[Format_Phone]],"(000) 000-0000") -> (872) 839-9920 | Q112: =CONCATENATE(TRIM(Table_Employee_Clean[[#This Row],[First_Name]])," ",TRIM(Table_Employee_Clean[[#This Row],[Last_Name]])) -> Eva Garcia | R112: =DATEDIF(Table_Employee_Clean[[#This Row],[Join_Date]], TODAY(), "y") -> 2 | S112: =CONCATENATE(TRIM(Table_Employee_Clean[[#This Row],[Name_Concat]])," FROM ",TRIM(Table_Employee_Clean[[#This Row],[Region]])) -> Eva Garcia FROM Texas
A113: EMP1111 | B113: Eva | C113: Davis | D113: 40 | E113: Cloud Tech | F113: Florida | G113: Pending | H113: 44453 | I113: 98981.36 | J113: eva.davis@example.com | K113: -9212493842 | L113: Good | M113: TRUE | N113: {=IF(Table_Employee!I113="N/A", IFERROR(MEDIAN(_xlfn._xlws.FILTER(Table_Employee_Clean[Salary], (Table_Employee_Clean[Department] = Table_Employee!E113) * (Table_Employee_Clean[Region] = Table_Employee!F113))), "N/A"), Table_Employee!I113)} -> 98981.36 | O113: =" "&SUBSTITUTE(Table_Employee_Clean[[#This Row],[Phone]],"-","") -> 9212493842 | P113: =TEXT(Table_Employee_Clean[[#This Row],[Format_Phone]],"(000) 000-0000") -> (921) 249-3842 | Q113: =CONCATENATE(TRIM(Table_Employee_Clean[[#This Row],[First_Name]])," ",TRIM(Table_Employee_Clean[[#This Row],[Last_Name]])) -> Eva Davis | R113: =DATEDIF(Table_Employee_Clean[[#This Row],[Join_Date]], TODAY(), "y") -> 5 | S113: =CONCATENATE(TRIM(Table_Employee_Clean[[#This Row],[Name_Concat]])," FROM ",TRIM(Table_Employee_Clean[[#This Row],[Region]])) -> Eva Davis FROM Florida
... A290: EMP1288 | B290: David | C290: Smith | D290: 30 | E290: Sales | F290: Nevada | G290: Inactive | H290: 45524 | I290: 79939.23 | J290: david.smith@example.com | K290: -8105955183 | L290: Excellent | M290: TRUE | N290: {=IF(Table_Employee!I290="N/A", IFERROR(MEDIAN(_xlfn._xlws.FILTER(Table_Employee_Clean[Salary], (Table_Employee_Clean[Department] = Table_Employee!E290) * (Table_Employee_Clean[Region] = Table_Employee!F290))), "N/A"), Table_Employee!I290)} -> 79939.23 | O290: =" "&SUBSTITUTE(Table_Employee_Clean[[#This Row],[Phone]],"-","") -> 8105955183 | P290: =TEXT(Table_Employee_Clean[[#This Row],[Format_Phone]],"(000) 000-0000") -> (810) 595-5183 | Q290: =CONCATENATE(TRIM(Table_Employee_Clean[[#This Row],[First_Name]])," ",TRIM(Table_Employee_Clean[[#This Row],[Last_Name]])) -> David Smith | R290: =DATEDIF(Table_Employee_Clean[[#This Row],[Join_Date]], TODAY(), "y") -> 2 | S290: =CONCATENATE(TRIM(Table_Employee_Clean[[#This Row],[Name_Concat]])," FROM ",TRIM(Table_Employee_Clean[[#This Row],[Region]])) -> David Smith FROM Nevada
A291: EMP1289 | B291: Grace | C291: Garcia | D291: 25 | E291: Admin | F291: New York | G291: Inactive | H291: 44493 | I291: N/A | J291: grace.garcia@example.com | K291: -2694500533 | L291: Poor | M291: FALSE | N291: {=IF(Table_Employee!I291="N/A", IFERROR(MEDIAN(_xlfn._xlws.FILTER(Table_Employee_Clean[Salary], (Table_Employee_Clean[Department] = Table_Employee!E291) * (Table_Employee_Clean[Region] = Table_Employee!F291))), "N/A"), Table_Employee!I291)} -> 77997.32 | O291: =" "&SUBSTITUTE(Table_Employee_Clean[[#This Row],[Phone]],"-","") -> 2694500533 | P291: =TEXT(Table_Employee_Clean[[#This Row],[Format_Phone]],"(000) 000-0000") -> (269) 450-0533 | Q291: =CONCATENATE(TRIM(Table_Employee_Clean[[#This Row],[First_Name]])," ",TRIM(Table_Employee_Clean[[#This Row],[Last_Name]])) -> Grace Garcia | R291: =DATEDIF(Table_Employee_Clean[[#This Row],[Join_Date]], TODAY(), "y") -> 4 | S291: =CONCATENATE(TRIM(Table_Employee_Clean[[#This Row],[Name_Concat]])," FROM ",TRIM(Table_Employee_Clean[[#This Row],[Region]])) -> Grace Garcia FROM New York
A292: EMP1290 | B292: Grace | C292: Smith | D292: 30 | E292: Finance | F292: California | G292: Inactive | H292: 44449 | I292: 90772.25 | J292: grace.smith@example.com | K292: -2408916497 | L292: Average | M292: FALSE | N292: {=IF(Table_Employee!I292="N/A", IFERROR(MEDIAN(_xlfn._xlws.FILTER(Table_Employee_Clean[Salary], (Table_Employee_Clean[Department] = Table_Employee!E292) * (Table_Employee_Clean[Region] = Table_Employee!F292))), "N/A"), Table_Employee!I292)} -> 90772.25 | O292: =" "&SUBSTITUTE(Table_Employee_Clean[[#This Row],[Phone]],"-","") -> 2408916497 | P292: =TEXT(Table_Employee_Clean[[#This Row],[Format_Phone]],"(000) 000-0000") -> (240) 891-6497 | Q292: =CONCATENATE(TRIM(Table_Employee_Clean[[#This Row],[First_Name]])," ",TRIM(Table_Employee_Clean[[#This Row],[Last_Name]])) -> Grace Smith | R292: =DATEDIF(Table_Employee_Clean[[#This Row],[Join_Date]], TODAY(), "y") -> 5 | S292: =CONCATENATE(TRIM(Table_Employee_Clean[[#This Row],[Name_Concat]])," FROM ",TRIM(Table_Employee_Clean[[#This Row],[Region]])) -> Grace Smith FROM California
A293: EMP1291 | B293: Eva | C293: Williams | D293: 35 | E293: DevOps | F293: New York | G293: Active | H293: 45198 | I293: 58275.74 | J293: eva.williams@example.com | K293: -3735439626 | L293: Good | M293: FALSE | N293: {=IF(Table_Employee!I293="N/A", IFERROR(MEDIAN(_xlfn._xlws.FILTER(Table_Employee_Clean[Salary], (Table_Employee_Clean[Department] = Table_Employee!E293) * (Table_Employee_Clean[Region] = Table_Employee!F293))), "N/A"), Table_Employee!I293)} -> 58275.74 | O293: =" "&SUBSTITUTE(Table_Employee_Clean[[#This Row],[Phone]],"-","") -> 3735439626 | P293: =TEXT(Table_Employee_Clean[[#This Row],[Format_Phone]],"(000) 000-0000") -> (373) 543-9626 | Q293: =CONCATENATE(TRIM(Table_Employee_Clean[[#This Row],[First_Name]])," ",TRIM(Table_Employee_Clean[[#This Row],[Last_Name]])) -> Eva Williams | R293: =DATEDIF(Table_Employee_Clean[[#This Row],[Join_Date]], TODAY(), "y") -> 3 | S293: =CONCATENATE(TRIM(Table_Employee_Clean[[#This Row],[Name_Concat]])," FROM ",TRIM(Table_Employee_Clean[[#This Row],[Region]])) -> Eva Williams FROM New York
A294: EMP1292 | B294: Grace | C294: Smith | D294: 30 | E294: DevOps | F294: California | G294: Pending | H294: 44071 | I294: 94709.79 | J294: grace.smith@example.com | K294: -3652717271 | L294: Excellent | M294: FALSE | N294: {=IF(Table_Employee!I294="N/A", IFERROR(MEDIAN(_xlfn._xlws.FILTER(Table_Employee_Clean[Salary], (Table_Employee_Clean[Department] = Table_Employee!E294) * (Table_Employee_Clean[Region] = Table_Employee!F294))), "N/A"), Table_Employee!I294)} -> 94709.79 | O294: =" "&SUBSTITUTE(Table_Employee_Clean[[#This Row],[Phone]],"-","") -> 3652717271 | P294: =TEXT(Table_Employee_Clean[[#This Row],[Format_Phone]],"(000) 000-0000") -> (365) 271-7271 | Q294: =CONCATENATE(TRIM(Table_Employee_Clean[[#This Row],[First_Name]])," ",TRIM(Table_Employee_Clean[[#This Row],[Last_Name]])) -> Grace Smith | R294: =DATEDIF(Table_Employee_Clean[[#This Row],[Join_Date]], TODAY(), "y") -> 6 | S294: =CONCATENATE(TRIM(Table_Employee_Clean[[#This Row],[Name_Concat]])," FROM ",TRIM(Table_Employee_Clean[[#This Row],[Region]])) -> Grace Smith FROM California
A295: EMP1293 | B295: Frank | C295: Johnson | D295: 30 | E295: Admin | F295: New York | G295: Active | H295: 44810 | I295: 60722.99 | J295: frank.johnson@example.com | K295: -2397240421 | L295: Excellent | M295: TRUE | N295: {=IF(Table_Employee!I295="N/A", IFERROR(MEDIAN(_xlfn._xlws.FILTER(Table_Employee_Clean[Salary], (Table_Employee_Clean[Department] = Table_Employee!E295) * (Table_Employee_Clean[Region] = Table_Employee!F295))), "N/A"), Table_Employee!I295)} -> 60722.99 | O295: =" "&SUBSTITUTE(Table_Employee_Clean[[#This Row],[Phone]],"-","") -> 2397240421 | P295: =TEXT(Table_Employee_Clean[[#This Row],[Format_Phone]],"(000) 000-0000") -> (239) 724-0421 | Q295: =CONCATENATE(TRIM(Table_Employee_Clean[[#This Row],[First_Name]])," ",TRIM(Table_Employee_Clean[[#This Row],[Last_Name]])) -> Frank Johnson | R295: =DATEDIF(Table_Employee_Clean[[#This Row],[Join_Date]], TODAY(), "y") -> 4 | S295: =CONCATENATE(TRIM(Table_Employee_Clean[[#This Row],[Name_Concat]])," FROM ",TRIM(Table_Employee_Clean[[#This Row],[Region]])) -> Frank Johnson FROM New York
A296: EMP1294 | B296: Frank | C296: Johnson | D296: 40 | E296: DevOps | F296: Illinois | G296: Inactive | H296: 45382 | I296: 87626.24 | J296: frank.johnson@example.com | K296: -6931216375 | L296: Good | M296: TRUE | N296: {=IF(Table_Employee!I296="N/A", IFERROR(MEDIAN(_xlfn._xlws.FILTER(Table_Employee_Clean[Salary], (Table_Employee_Clean[Department] = Table_Employee!E296) * (Table_Employee_Clean[Region] = Table_Employee!F296))), "N/A"), Table_Employee!I296)} -> 87626.24 | O296: =" "&SUBSTITUTE(Table_Employee_Clean[[#This Row],[Phone]],"-","") -> 6931216375 | P296: =TEXT(Table_Employee_Clean[[#This Row],[Format_Phone]],"(000) 000-0000") -> (693) 121-6375 | Q296: =CONCATENATE(TRIM(Table_Employee_Clean[[#This Row],[First_Name]])," ",TRIM(Table_Employee_Clean[[#This Row],[Last_Name]])) -> Frank Johnson | R296: =DATEDIF(Table_Employee_Clean[[#This Row],[Join_Date]], TODAY(), "y") -> 2 | S296: =CONCATENATE(TRIM(Table_Employee_Clean[[#This Row],[Name_Concat]])," FROM ",TRIM(Table_Employee_Clean[[#This Row],[Region]])) -> Frank Johnson FROM Illinois
A297: EMP1295 | B297: David | C297: Brown | D297: 30 | E297: DevOps | F297: Illinois | G297: Active | H297: 44907 | I297: 81272.36 | J297: david.brown@example.com | K297: -1820916600 | L297: Poor | M297: FALSE | N297: {=IF(Table_Employee!I297="N/A", IFERROR(MEDIAN(_xlfn._xlws.FILTER(Table_Employee_Clean[Salary], (Table_Employee_Clean[Department] = Table_Employee!E297) * (Table_Employee_Clean[Region] = Table_Employee!F297))), "N/A"), Table_Employee!I297)} -> 81272.36 | O297: =" "&SUBSTITUTE(Table_Employee_Clean[[#This Row],[Phone]],"-","") -> 1820916600 | P297: =TEXT(Table_Employee_Clean[[#This Row],[Format_Phone]],"(000) 000-0000") -> (182) 091-6600 | Q297: =CONCATENATE(TRIM(Table_Employee_Clean[[#This Row],[First_Name]])," ",TRIM(Table_Employee_Clean[[#This Row],[Last_Name]])) -> David Brown | R297: =DATEDIF(Table_Employee_Clean[[#This Row],[Join_Date]], TODAY(), "y") -> 3 | S297: =CONCATENATE(TRIM(Table_Employee_Clean[[#This Row],[Name_Concat]])," FROM ",TRIM(Table_Employee_Clean[[#This Row],[Region]])) -> David Brown FROM Illinois
A298: EMP1296 | B298: Bob | C298: Miller | D298: 30 | E298: Cloud Tech | F298: Texas | G298: Pending | H298: 44866 | I298: 64150.97 | J298: bob.miller@example.com | K298: -23142899 | L298: Good | M298: TRUE | N298: {=IF(Table_Employee!I298="N/A", IFERROR(MEDIAN(_xlfn._xlws.FILTER(Table_Employee_Clean[Salary], (Table_Employee_Clean[Department] = Table_Employee!E298) * (Table_Employee_Clean[Region] = Table_Employee!F298))), "N/A"), Table_Employee!I298)} -> 64150.97 | O298: =" "&SUBSTITUTE(Table_Employee_Clean[[#This Row],[Phone]],"-","") -> 23142899 | P298: =TEXT(Table_Employee_Clean[[#This Row],[Format_Phone]],"(000) 000-0000") -> (002) 314-2899 | Q298: =CONCATENATE(TRIM(Table_Employee_Clean[[#This Row],[First_Name]])," ",TRIM(Table_Employee_Clean[[#This Row],[Last_Name]])) -> Bob Miller | R298: =DATEDIF(Table_Employee_Clean[[#This Row],[Join_Date]], TODAY(), "y") -> 3 | S298: =CONCATENATE(TRIM(Table_Employee_Clean[[#This Row],[Name_Concat]])," FROM ",TRIM(Table_Employee_Clean[[#This Row],[Region]])) -> Bob Miller FROM Texas
A299: EMP1297 | B299: Charlie | C299: Davis | D299: 35 | E299: Sales | F299: Florida | G299: Active | H299: 45224 | I299: 64378.1 | J299: charlie.davis@example.com | K299: -1851327971 | L299: Poor | M299: FALSE | N299: {=IF(Table_Employee!I299="N/A", IFERROR(MEDIAN(_xlfn._xlws.FILTER(Table_Employee_Clean[Salary], (Table_Employee_Clean[Department] = Table_Employee!E299) * (Table_Employee_Clean[Region] = Table_Employee!F299))), "N/A"), Table_Employee!I299)} -> 64378.1 | O299: =" "&SUBSTITUTE(Table_Employee_Clean[[#This Row],[Phone]],"-","") -> 1851327971 | P299: =TEXT(Table_Employee_Clean[[#This Row],[Format_Phone]],"(000) 000-0000") -> (185) 132-7971 | Q299: =CONCATENATE(TRIM(Table_Employee_Clean[[#This Row],[First_Name]])," ",TRIM(Table_Employee_Clean[[#This Row],[Last_Name]])) -> Charlie Davis | R299: =DATEDIF(Table_Employee_Clean[[#This Row],[Join_Date]], TODAY(), "y") -> 2 | S299: =CONCATENATE(TRIM(Table_Employee_Clean[[#This Row],[Name_Concat]])," FROM ",TRIM(Table_Employee_Clean[[#This Row],[Region]])) -> Charlie Davis FROM Florida
A300: EMP1298 | B300: Bob | C300: Jones | D300: 30 | E300: Finance | F300: Texas | G300: Inactive | H300: 44101 | I300: 85927.35 | J300: bob.jones@example.com | K300: -4572308480 | L300: Good | M300: FALSE | N300: {=IF(Table_Employee!I300="N/A", IFERROR(MEDIAN(_xlfn._xlws.FILTER(Table_Employee_Clean[Salary], (Table_Employee_Clean[Department] = Table_Employee!E300) * (Table_Employee_Clean[Region] = Table_Employee!F300))), "N/A"), Table_Employee!I300)} -> 85927.35 | O300: =" "&SUBSTITUTE(Table_Employee_Clean[[#This Row],[Phone]],"-","") -> 4572308480 | P300: =TEXT(Table_Employee_Clean[[#This Row],[Format_Phone]],"(000) 000-0000") -> (457) 230-8480 | Q300: =CONCATENATE(TRIM(Table_Employee_Clean[[#This Row],[First_Name]])," ",TRIM(Table_Employee_Clean[[#This Row],[Last_Name]])) -> Bob Jones | R300: =DATEDIF(Table_Employee_Clean[[#This Row],[Join_Date]], TODAY(), "y") -> 6 | S300: =CONCATENATE(TRIM(Table_Employee_Clean[[#This Row],[Name_Concat]])," FROM ",TRIM(Table_Employee_Clean[[#This Row],[Region]])) -> Bob Jones FROM Texas
A301: EMP1299 | B301: Alice | C301: Garcia | D301: 30 | E301: Finance | F301: Nevada | G301: Inactive | H301: 45312 | I301: 51523.93 | J301: alice.garcia@example.com | K301: -18418619 | L301: Average | M301: TRUE | N301: {=IF(Table_Employee!I301="N/A", IFERROR(MEDIAN(_xlfn._xlws.FILTER(Table_Employee_Clean[Salary], (Table_Employee_Clean[Department] = Table_Employee!E301) * (Table_Employee_Clean[Region] = Table_Employee!F301))), "N/A"), Table_Employee!I301)} -> 51523.93 | O301: =" "&SUBSTITUTE(Table_Employee_Clean[[#This Row],[Phone]],"-","") -> 18418619 | P301: =TEXT(Table_Employee_Clean[[#This Row],[Format_Phone]],"(000) 000-0000") -> (001) 841-8619 | Q301: =CONCATENATE(TRIM(Table_Employee_Clean[[#This Row],[First_Name]])," ",TRIM(Table_Employee_Clean[[#This Row],[Last_Name]])) -> Alice Garcia | R301: =DATEDIF(Table_Employee_Clean[[#This Row],[Join_Date]], TODAY(), "y") -> 2 | S301: =CONCATENATE(TRIM(Table_Employee_Clean[[#This Row],[Name_Concat]])," FROM ",TRIM(Table_Employee_Clean[[#This Row],[Region]])) -> Alice Garcia FROM Nevada
A302: EMP1300 | B302: Alice | C302: Smith | D302: 30 | E302: Sales | F302: Texas | G302: Active | H302: 44698 | I302: 74117.02 | J302: alice.smith@example.com | K302: -3036625435 | L302: Poor | M302: FALSE | N302: {=IF(Table_Employee!I302="N/A", IFERROR(MEDIAN(_xlfn._xlws.FILTER(Table_Employee_Clean[Salary], (Table_Employee_Clean[Department] = Table_Employee!E302) * (Table_Employee_Clean[Region] = Table_Employee!F302))), "N/A"), Table_Employee!I302)} -> 74117.02 | O302: =" "&SUBSTITUTE(Table_Employee_Clean[[#This Row],[Phone]],"-","") -> 3036625435 | P302: =TEXT(Table_Employee_Clean[[#This Row],[Format_Phone]],"(000) 000-0000") -> (303) 662-5435 | Q302: =CONCATENATE(TRIM(Table_Employee_Clean[[#This Row],[First_Name]])," ",TRIM(Table_Employee_Clean[[#This Row],[Last_Name]])) -> Alice Smith | R302: =DATEDIF(Table_Employee_Clean[[#This Row],[Join_Date]], TODAY(), "y") -> 4 | S302: =CONCATENATE(TRIM(Table_Employee_Clean[[#This Row],[Name_Concat]])," FROM ",TRIM(Table_Employee_Clean[[#This Row],[Region]])) -> Alice Smith FROM Texas
...

Sheet MessyWorkChart
A3: Row Labels | B3: Sum of Salary_fill
A4: Heidi Johnson | B4: 1777718.7
A5: Bob Garcia | B5: 1783326.3 | T5: Row Labels | U5: Count of Department
A6: Eva Jones | B6: 1808280.8 | F6: =COUNTA(Table_Employee_Clean[Employee_ID]) -> 1020 | T6: Admin | U6: 166
A7: David Johnson | B7: 1821773.3 | F7: =AVERAGE(Table_Employee_Clean[Salary_fill]) -> 85173.29 | T7: Cloud Tech | U7: 146
A8: Charlie Jones | B8: 1833846.9 | T8: DevOps | U8: 189
A9: Grace Smith | B9: 1905834.7 | T9: Finance | U9: 170
A10: Eva Miller | B10: 1945133.6 | T10: HR | U10: 171
A11: Frank Brown | B11: 1955758.7 | T11: Sales | U11: 178
A12: Frank Smith | B12: 2116556.5 | T12: Grand Total | U12: 1020
A13: Grace Brown | B13: 2436583.8
A14: Grand Total | B14: 19384813
A17: Row Labels | B17: Sum of Salary_fill
A18: DevOps | B18: 16264044
A19: Sales | B19: 15458515
A20: HR | B20: 14629238 | N20: =SUM(Table_Employee_Clean[Salary_fill]) -> 86876756
A21: Admin | B21: 14147961
A22: Finance | B22: 13975158
A23: Cloud Tech | B23: 12401841
A24: Grand Total | B24: 86876756
B38: Row Labels | C38: Count of Employee_ID
B39: California | C39: 187
B40: Florida | C40: 185 | R40: =COUNTIF(Table_Employee_Clean[Status],"Active")/COUNTA(Table_Employee_Clean[Status]) -> 0.34509804
B41: Illinois | C41: 165 | R41: =COUNTIF(Table_Employee_Clean[Status],"Inactive")/COUNTA(Table_Employee_Clean[Status]) -> 0.30588235
B42: Nevada | C42: 169 | R42: =COUNTIF(Table_Employee_Clean[Status],"pending")/COUNTA(Table_Employee_Clean[Status]) -> 0.34901961
B43: New York | C43: 161
B44: Texas | C44: 153
B45: Grand Total | C45: 1020
G47: Row Labels | H47: Count of Employee_ID
G48: California | H48: 187
G49: Florida | H49: 185
G50: Illinois | H50: 165
G51: Nevada | H51: 169
G52: New York | H52: 161
G53: Texas | H53: 153
G54: Grand Total | H54: 1020

Sheet Dashboard
D21: HIGEST SALARY | E21: Max of Salary_fill | G21: Row Labels | H21: Sum of Salary_fill
D22: Admin | G22: DevOps | H22: 16264044
D23: Bob Brown | E23: 119152.47 | G23: Sales | H23: 15458515
D24: Charlie Garcia | E24: 108210.15 | G24: HR | H24: 14629238
D25: Eva Davis | E25: 103140.67 | G25: Admin | H25: 14147961
D26: Cloud Tech | G26: Finance | H26: 13975158
D27: David Johnson | E27: 119217.46 | G27: Cloud Tech | H27: 12401841
D28: Charlie Brown | E28: 100371
D29: Bob Jones | E29: 98143.67
D30: DevOps
D31: Grace Brown | E31: 119586.11
D32: Grace Smith | E32: 114770.32
D33: Frank Johnson | E33: 109229.68
D34: Finance
D35: Frank Brown | E35: 116353.31
D36: Frank Smith | E36: 112120.71
D37: Grace Brown | E37: 109523.4
D38: HR
D39: Frank Smith | E39: 118456.11
D40: Eva Williams | E40: 116680.63
D41: Bob Davis | E41: 115022.1
D42: Sales
D43: Frank Jones | E43: 118907.63
D44: Grace Jones | E44: 117975.49
D45: David Garcia | E45: 98752.97
